Exception at 09-02-2025 : 13-48-30
.............................................
In redis.connection
Message: Exception while retrieving IPs list from Redis
Traceback :
 ............
Traceback (most recent call last):
  File "C:\Users\45422\AppData\Local\Programs\Python\Python311\Lib\site-packages\redis\connection.py", line 357, in connect
    sock = self.retry.call_with_retry(
           ^^^^^^^^^^^^^^^^^^^^^^^^^^^
  File "C:\Users\45422\AppData\Local\Programs\Python\Python311\Lib\site-packages\redis\retry.py", line 62, in call_with_retry
    return do()
           ^^^^
  File "C:\Users\45422\AppData\Local\Programs\Python\Python311\Lib\site-packages\redis\connection.py", line 358, in <lambda>
    lambda: self._connect(), lambda error: self.disconnect(error)
            ^^^^^^^^^^^^^^^
  File "C:\Users\45422\AppData\Local\Programs\Python\Python311\Lib\site-packages\redis\connection.py", line 730, in _connect
    raise err
  File "C:\Users\45422\AppData\Local\Programs\Python\Python311\Lib\site-packages\redis\connection.py", line 718, in _connect
    sock.connect(socket_address)
ConnectionRefusedError: [WinError 10061] No connection could be made because the target machine actively refused it

During handling of the above exception, another exception occurred:

Traceback (most recent call last):
  File "C:\Users\45422\Desktop\API_version\ThesisProject2\dicom_server\redis_handler.py", line 14, in is_ip_scanned
    return ip.encode() in self.redis_client.lrange("scannedIPs", 0, -1)
                          ^^^^^^^^^^^^^^^^^^^^^^^^^^^^^^^^^^^^^^^^^^^^^
  File "C:\Users\45422\AppData\Local\Programs\Python\Python311\Lib\site-packages\redis\commands\core.py", line 2748, in lrange
    return self.execute_command("LRANGE", name, start, end, keys=[name])
           ^^^^^^^^^^^^^^^^^^^^^^^^^^^^^^^^^^^^^^^^^^^^^^^^^^^^^^^^^^^^^
  File "C:\Users\45422\AppData\Local\Programs\Python\Python311\Lib\site-packages\redis\client.py", line 559, in execute_command
    return self._execute_command(*args, **options)
           ^^^^^^^^^^^^^^^^^^^^^^^^^^^^^^^^^^^^^^^
  File "C:\Users\45422\AppData\Local\Programs\Python\Python311\Lib\site-packages\redis\client.py", line 565, in _execute_command
    conn = self.connection or pool.get_connection(command_name, **options)
                              ^^^^^^^^^^^^^^^^^^^^^^^^^^^^^^^^^^^^^^^^^^^^
  File "C:\Users\45422\AppData\Local\Programs\Python\Python311\Lib\site-packages\redis\connection.py", line 1422, in get_connection
    connection.connect()
  File "C:\Users\45422\AppData\Local\Programs\Python\Python311\Lib\site-packages\redis\connection.py", line 363, in connect
    raise ConnectionError(self._error_message(e))
redis.exceptions.ConnectionError: Error 10061 connecting to localhost:6379. No connection could be made because the target machine actively refused it.

Exception at 09-02-2025 : 13-48-34
.............................................
In redis.connection
Message: Exception while adding a scanned IP to the scanned list
Traceback :
 ............
Traceback (most recent call last):
  File "C:\Users\45422\AppData\Local\Programs\Python\Python311\Lib\site-packages\redis\connection.py", line 357, in connect
    sock = self.retry.call_with_retry(
           ^^^^^^^^^^^^^^^^^^^^^^^^^^^
  File "C:\Users\45422\AppData\Local\Programs\Python\Python311\Lib\site-packages\redis\retry.py", line 62, in call_with_retry
    return do()
           ^^^^
  File "C:\Users\45422\AppData\Local\Programs\Python\Python311\Lib\site-packages\redis\connection.py", line 358, in <lambda>
    lambda: self._connect(), lambda error: self.disconnect(error)
            ^^^^^^^^^^^^^^^
  File "C:\Users\45422\AppData\Local\Programs\Python\Python311\Lib\site-packages\redis\connection.py", line 730, in _connect
    raise err
  File "C:\Users\45422\AppData\Local\Programs\Python\Python311\Lib\site-packages\redis\connection.py", line 718, in _connect
    sock.connect(socket_address)
ConnectionRefusedError: [WinError 10061] No connection could be made because the target machine actively refused it

During handling of the above exception, another exception occurred:

Traceback (most recent call last):
  File "C:\Users\45422\Desktop\API_version\ThesisProject2\dicom_server\redis_handler.py", line 22, in add_scanned_ip
    self.redis_client.rpush("scannedIPs", ip)
  File "C:\Users\45422\AppData\Local\Programs\Python\Python311\Lib\site-packages\redis\commands\core.py", line 2818, in rpush
    return self.execute_command("RPUSH", name, *values)
           ^^^^^^^^^^^^^^^^^^^^^^^^^^^^^^^^^^^^^^^^^^^^
  File "C:\Users\45422\AppData\Local\Programs\Python\Python311\Lib\site-packages\redis\client.py", line 559, in execute_command
    return self._execute_command(*args, **options)
           ^^^^^^^^^^^^^^^^^^^^^^^^^^^^^^^^^^^^^^^
  File "C:\Users\45422\AppData\Local\Programs\Python\Python311\Lib\site-packages\redis\client.py", line 565, in _execute_command
    conn = self.connection or pool.get_connection(command_name, **options)
                              ^^^^^^^^^^^^^^^^^^^^^^^^^^^^^^^^^^^^^^^^^^^^
  File "C:\Users\45422\AppData\Local\Programs\Python\Python311\Lib\site-packages\redis\connection.py", line 1422, in get_connection
    connection.connect()
  File "C:\Users\45422\AppData\Local\Programs\Python\Python311\Lib\site-packages\redis\connection.py", line 363, in connect
    raise ConnectionError(self._error_message(e))
redis.exceptions.ConnectionError: Error 10061 connecting to localhost:6379. No connection could be made because the target machine actively refused it.

Exception at 09-02-2025 : 13-48-34
.............................................
In dicom_session_manager
Message: Exception while getting session requestor reputation data
Traceback :
 ............
Traceback (most recent call last):
  File "C:\Users\45422\Desktop\API_version\ThesisProject2\dicom_server\dicom_session_manager.py", line 47, in get_session_requestor_reputation
    rep_dat = self.threat_intelligence.get_reputation_data(ip, ip_scanned)
              ^^^^^^^^^^^^^^^^^^^^^^^^^^^^^^^^^^^^^^^^^^^^^^^^^^^^^^^^^^^^
TypeError: ThreatIntelligence.get_reputation_data() missing 1 required positional argument: 'ip_scanned'

Exception at 09-02-2025 : 13-48-38
.............................................
In redis.connection
Message: Exception while adding a request information to Redis
Traceback :
 ............
Traceback (most recent call last):
  File "C:\Users\45422\AppData\Local\Programs\Python\Python311\Lib\site-packages\redis\connection.py", line 357, in connect
    sock = self.retry.call_with_retry(
           ^^^^^^^^^^^^^^^^^^^^^^^^^^^
  File "C:\Users\45422\AppData\Local\Programs\Python\Python311\Lib\site-packages\redis\retry.py", line 62, in call_with_retry
    return do()
           ^^^^
  File "C:\Users\45422\AppData\Local\Programs\Python\Python311\Lib\site-packages\redis\connection.py", line 358, in <lambda>
    lambda: self._connect(), lambda error: self.disconnect(error)
            ^^^^^^^^^^^^^^^
  File "C:\Users\45422\AppData\Local\Programs\Python\Python311\Lib\site-packages\redis\connection.py", line 730, in _connect
    raise err
  File "C:\Users\45422\AppData\Local\Programs\Python\Python311\Lib\site-packages\redis\connection.py", line 718, in _connect
    sock.connect(socket_address)
ConnectionRefusedError: [WinError 10061] No connection could be made because the target machine actively refused it

During handling of the above exception, another exception occurred:

Traceback (most recent call last):
  File "C:\Users\45422\Desktop\API_version\ThesisProject2\dicom_server\redis_handler.py", line 36, in add_request_data
    self.redis_client.rpush("requests", redis_log_data)
  File "C:\Users\45422\AppData\Local\Programs\Python\Python311\Lib\site-packages\redis\commands\core.py", line 2818, in rpush
    return self.execute_command("RPUSH", name, *values)
           ^^^^^^^^^^^^^^^^^^^^^^^^^^^^^^^^^^^^^^^^^^^^
  File "C:\Users\45422\AppData\Local\Programs\Python\Python311\Lib\site-packages\redis\client.py", line 559, in execute_command
    return self._execute_command(*args, **options)
           ^^^^^^^^^^^^^^^^^^^^^^^^^^^^^^^^^^^^^^^
  File "C:\Users\45422\AppData\Local\Programs\Python\Python311\Lib\site-packages\redis\client.py", line 565, in _execute_command
    conn = self.connection or pool.get_connection(command_name, **options)
                              ^^^^^^^^^^^^^^^^^^^^^^^^^^^^^^^^^^^^^^^^^^^^
  File "C:\Users\45422\AppData\Local\Programs\Python\Python311\Lib\site-packages\redis\connection.py", line 1422, in get_connection
    connection.connect()
  File "C:\Users\45422\AppData\Local\Programs\Python\Python311\Lib\site-packages\redis\connection.py", line 363, in connect
    raise ConnectionError(self._error_message(e))
redis.exceptions.ConnectionError: Error 10061 connecting to localhost:6379. No connection could be made because the target machine actively refused it.

Exception at 09-02-2025 : 14-04-01
.............................................
In redis.connection
Message: Exception while retrieving IPs list from Redis
Traceback :
 ............
Traceback (most recent call last):
  File "/home/ls/.local/lib/python3.10/site-packages/redis/connection.py", line 357, in connect
    sock = self.retry.call_with_retry(
  File "/home/ls/.local/lib/python3.10/site-packages/redis/retry.py", line 62, in call_with_retry
    return do()
  File "/home/ls/.local/lib/python3.10/site-packages/redis/connection.py", line 358, in <lambda>
    lambda: self._connect(), lambda error: self.disconnect(error)
  File "/home/ls/.local/lib/python3.10/site-packages/redis/connection.py", line 730, in _connect
    raise err
  File "/home/ls/.local/lib/python3.10/site-packages/redis/connection.py", line 718, in _connect
    sock.connect(socket_address)
ConnectionRefusedError: [Errno 111] Connection refused

During handling of the above exception, another exception occurred:

Traceback (most recent call last):
  File "/mnt/c/Users/45422/Desktop/API_version/ThesisProject2/dicom_server/redis_handler.py", line 14, in is_ip_scanned
    return ip.encode() in self.redis_client.lrange("scannedIPs", 0, -1)
  File "/home/ls/.local/lib/python3.10/site-packages/redis/commands/core.py", line 2748, in lrange
    return self.execute_command("LRANGE", name, start, end, keys=[name])
  File "/home/ls/.local/lib/python3.10/site-packages/redis/client.py", line 559, in execute_command
    return self._execute_command(*args, **options)
  File "/home/ls/.local/lib/python3.10/site-packages/redis/client.py", line 565, in _execute_command
    conn = self.connection or pool.get_connection(command_name, **options)
  File "/home/ls/.local/lib/python3.10/site-packages/redis/connection.py", line 1422, in get_connection
    connection.connect()
  File "/home/ls/.local/lib/python3.10/site-packages/redis/connection.py", line 363, in connect
    raise ConnectionError(self._error_message(e))
redis.exceptions.ConnectionError: Error 111 connecting to localhost:6379. Connection refused.

Exception at 09-02-2025 : 14-04-01
.............................................
In redis.connection
Message: Exception while adding a scanned IP to the scanned list
Traceback :
 ............
Traceback (most recent call last):
  File "/home/ls/.local/lib/python3.10/site-packages/redis/connection.py", line 357, in connect
    sock = self.retry.call_with_retry(
  File "/home/ls/.local/lib/python3.10/site-packages/redis/retry.py", line 62, in call_with_retry
    return do()
  File "/home/ls/.local/lib/python3.10/site-packages/redis/connection.py", line 358, in <lambda>
    lambda: self._connect(), lambda error: self.disconnect(error)
  File "/home/ls/.local/lib/python3.10/site-packages/redis/connection.py", line 730, in _connect
    raise err
  File "/home/ls/.local/lib/python3.10/site-packages/redis/connection.py", line 718, in _connect
    sock.connect(socket_address)
ConnectionRefusedError: [Errno 111] Connection refused

During handling of the above exception, another exception occurred:

Traceback (most recent call last):
  File "/mnt/c/Users/45422/Desktop/API_version/ThesisProject2/dicom_server/redis_handler.py", line 22, in add_scanned_ip
    self.redis_client.rpush("scannedIPs", ip)
  File "/home/ls/.local/lib/python3.10/site-packages/redis/commands/core.py", line 2818, in rpush
    return self.execute_command("RPUSH", name, *values)
  File "/home/ls/.local/lib/python3.10/site-packages/redis/client.py", line 559, in execute_command
    return self._execute_command(*args, **options)
  File "/home/ls/.local/lib/python3.10/site-packages/redis/client.py", line 565, in _execute_command
    conn = self.connection or pool.get_connection(command_name, **options)
  File "/home/ls/.local/lib/python3.10/site-packages/redis/connection.py", line 1422, in get_connection
    connection.connect()
  File "/home/ls/.local/lib/python3.10/site-packages/redis/connection.py", line 363, in connect
    raise ConnectionError(self._error_message(e))
redis.exceptions.ConnectionError: Error 111 connecting to localhost:6379. Connection refused.

Exception at 09-02-2025 : 14-04-01
.............................................
In dicom_session_manager
Message: Exception while getting session requestor reputation data
Traceback :
 ............
Traceback (most recent call last):
  File "/mnt/c/Users/45422/Desktop/API_version/ThesisProject2/dicom_server/dicom_session_manager.py", line 47, in get_session_requestor_reputation
    rep_dat = self.threat_intelligence.get_reputation_data(ip, ip_scanned)
TypeError: ThreatIntelligence.get_reputation_data() missing 1 required positional argument: 'ip_scanned'

Exception at 09-02-2025 : 14-04-02
.............................................
In redis.connection
Message: Exception while adding a request information to Redis
Traceback :
 ............
Traceback (most recent call last):
  File "/home/ls/.local/lib/python3.10/site-packages/redis/connection.py", line 357, in connect
    sock = self.retry.call_with_retry(
  File "/home/ls/.local/lib/python3.10/site-packages/redis/retry.py", line 62, in call_with_retry
    return do()
  File "/home/ls/.local/lib/python3.10/site-packages/redis/connection.py", line 358, in <lambda>
    lambda: self._connect(), lambda error: self.disconnect(error)
  File "/home/ls/.local/lib/python3.10/site-packages/redis/connection.py", line 730, in _connect
    raise err
  File "/home/ls/.local/lib/python3.10/site-packages/redis/connection.py", line 718, in _connect
    sock.connect(socket_address)
ConnectionRefusedError: [Errno 111] Connection refused

During handling of the above exception, another exception occurred:

Traceback (most recent call last):
  File "/mnt/c/Users/45422/Desktop/API_version/ThesisProject2/dicom_server/redis_handler.py", line 36, in add_request_data
    self.redis_client.rpush("requests", redis_log_data)
  File "/home/ls/.local/lib/python3.10/site-packages/redis/commands/core.py", line 2818, in rpush
    return self.execute_command("RPUSH", name, *values)
  File "/home/ls/.local/lib/python3.10/site-packages/redis/client.py", line 559, in execute_command
    return self._execute_command(*args, **options)
  File "/home/ls/.local/lib/python3.10/site-packages/redis/client.py", line 565, in _execute_command
    conn = self.connection or pool.get_connection(command_name, **options)
  File "/home/ls/.local/lib/python3.10/site-packages/redis/connection.py", line 1422, in get_connection
    connection.connect()
  File "/home/ls/.local/lib/python3.10/site-packages/redis/connection.py", line 363, in connect
    raise ConnectionError(self._error_message(e))
redis.exceptions.ConnectionError: Error 111 connecting to localhost:6379. Connection refused.

Exception at 09-02-2025 : 15-24-20
.............................................
In redis.connection
Message: Exception while retrieving IPs list from Redis
Traceback :
 ............
Traceback (most recent call last):
  File "/home/ls/.local/lib/python3.10/site-packages/redis/connection.py", line 357, in connect
    sock = self.retry.call_with_retry(
  File "/home/ls/.local/lib/python3.10/site-packages/redis/retry.py", line 62, in call_with_retry
    return do()
  File "/home/ls/.local/lib/python3.10/site-packages/redis/connection.py", line 358, in <lambda>
    lambda: self._connect(), lambda error: self.disconnect(error)
  File "/home/ls/.local/lib/python3.10/site-packages/redis/connection.py", line 730, in _connect
    raise err
  File "/home/ls/.local/lib/python3.10/site-packages/redis/connection.py", line 718, in _connect
    sock.connect(socket_address)
ConnectionRefusedError: [Errno 111] Connection refused

During handling of the above exception, another exception occurred:

Traceback (most recent call last):
  File "/mnt/c/Users/45422/Desktop/API_version/ThesisProject2/dicom_server/redis_handler.py", line 14, in is_ip_scanned
    return ip.encode() in self.redis_client.lrange("scannedIPs", 0, -1)
  File "/home/ls/.local/lib/python3.10/site-packages/redis/commands/core.py", line 2748, in lrange
    return self.execute_command("LRANGE", name, start, end, keys=[name])
  File "/home/ls/.local/lib/python3.10/site-packages/redis/client.py", line 559, in execute_command
    return self._execute_command(*args, **options)
  File "/home/ls/.local/lib/python3.10/site-packages/redis/client.py", line 565, in _execute_command
    conn = self.connection or pool.get_connection(command_name, **options)
  File "/home/ls/.local/lib/python3.10/site-packages/redis/connection.py", line 1422, in get_connection
    connection.connect()
  File "/home/ls/.local/lib/python3.10/site-packages/redis/connection.py", line 363, in connect
    raise ConnectionError(self._error_message(e))
redis.exceptions.ConnectionError: Error 111 connecting to localhost:6379. Connection refused.

Exception at 09-02-2025 : 15-24-20
.............................................
In redis.connection
Message: Exception while adding a scanned IP to the scanned list
Traceback :
 ............
Traceback (most recent call last):
  File "/home/ls/.local/lib/python3.10/site-packages/redis/connection.py", line 357, in connect
    sock = self.retry.call_with_retry(
  File "/home/ls/.local/lib/python3.10/site-packages/redis/retry.py", line 62, in call_with_retry
    return do()
  File "/home/ls/.local/lib/python3.10/site-packages/redis/connection.py", line 358, in <lambda>
    lambda: self._connect(), lambda error: self.disconnect(error)
  File "/home/ls/.local/lib/python3.10/site-packages/redis/connection.py", line 730, in _connect
    raise err
  File "/home/ls/.local/lib/python3.10/site-packages/redis/connection.py", line 718, in _connect
    sock.connect(socket_address)
ConnectionRefusedError: [Errno 111] Connection refused

During handling of the above exception, another exception occurred:

Traceback (most recent call last):
  File "/mnt/c/Users/45422/Desktop/API_version/ThesisProject2/dicom_server/redis_handler.py", line 22, in add_scanned_ip
    self.redis_client.rpush("scannedIPs", ip)
  File "/home/ls/.local/lib/python3.10/site-packages/redis/commands/core.py", line 2818, in rpush
    return self.execute_command("RPUSH", name, *values)
  File "/home/ls/.local/lib/python3.10/site-packages/redis/client.py", line 559, in execute_command
    return self._execute_command(*args, **options)
  File "/home/ls/.local/lib/python3.10/site-packages/redis/client.py", line 565, in _execute_command
    conn = self.connection or pool.get_connection(command_name, **options)
  File "/home/ls/.local/lib/python3.10/site-packages/redis/connection.py", line 1422, in get_connection
    connection.connect()
  File "/home/ls/.local/lib/python3.10/site-packages/redis/connection.py", line 363, in connect
    raise ConnectionError(self._error_message(e))
redis.exceptions.ConnectionError: Error 111 connecting to localhost:6379. Connection refused.

Exception at 09-02-2025 : 15-24-20
.............................................
In dicom_session_manager
Message: Exception while getting session requestor reputation data
Traceback :
 ............
Traceback (most recent call last):
  File "/mnt/c/Users/45422/Desktop/API_version/ThesisProject2/dicom_server/dicom_session_manager.py", line 47, in get_session_requestor_reputation
    rep_dat = self.threat_intelligence.get_reputation_data(ip, ip_scanned)
TypeError: ThreatIntelligence.get_reputation_data() missing 1 required positional argument: 'ip_scanned'

Exception at 09-02-2025 : 15-24-20
.............................................
In redis.connection
Message: Exception while adding a request information to Redis
Traceback :
 ............
Traceback (most recent call last):
  File "/home/ls/.local/lib/python3.10/site-packages/redis/connection.py", line 357, in connect
    sock = self.retry.call_with_retry(
  File "/home/ls/.local/lib/python3.10/site-packages/redis/retry.py", line 62, in call_with_retry
    return do()
  File "/home/ls/.local/lib/python3.10/site-packages/redis/connection.py", line 358, in <lambda>
    lambda: self._connect(), lambda error: self.disconnect(error)
  File "/home/ls/.local/lib/python3.10/site-packages/redis/connection.py", line 730, in _connect
    raise err
  File "/home/ls/.local/lib/python3.10/site-packages/redis/connection.py", line 718, in _connect
    sock.connect(socket_address)
ConnectionRefusedError: [Errno 111] Connection refused

During handling of the above exception, another exception occurred:

Traceback (most recent call last):
  File "/mnt/c/Users/45422/Desktop/API_version/ThesisProject2/dicom_server/redis_handler.py", line 36, in add_request_data
    self.redis_client.rpush("requests", redis_log_data)
  File "/home/ls/.local/lib/python3.10/site-packages/redis/commands/core.py", line 2818, in rpush
    return self.execute_command("RPUSH", name, *values)
  File "/home/ls/.local/lib/python3.10/site-packages/redis/client.py", line 559, in execute_command
    return self._execute_command(*args, **options)
  File "/home/ls/.local/lib/python3.10/site-packages/redis/client.py", line 565, in _execute_command
    conn = self.connection or pool.get_connection(command_name, **options)
  File "/home/ls/.local/lib/python3.10/site-packages/redis/connection.py", line 1422, in get_connection
    connection.connect()
  File "/home/ls/.local/lib/python3.10/site-packages/redis/connection.py", line 363, in connect
    raise ConnectionError(self._error_message(e))
redis.exceptions.ConnectionError: Error 111 connecting to localhost:6379. Connection refused.

Exception at 09-02-2025 : 15-25-00
.............................................
In dicom_session_manager
Message: Exception while getting session requestor reputation data
Traceback :
 ............
Traceback (most recent call last):
  File "/mnt/c/Users/45422/Desktop/API_version/ThesisProject2/dicom_server/dicom_session_manager.py", line 47, in get_session_requestor_reputation
    rep_dat = self.threat_intelligence.get_reputation_data(ip, ip_scanned)
TypeError: ThreatIntelligence.get_reputation_data() missing 1 required positional argument: 'ip_scanned'

