Exception at 25-02-2025 : 10-48-34
.............................................
In db
Message: Exception in SERIES level query
Traceback :
 ............
Traceback (most recent call last):
  File "C:\Users\45422\Desktop\API_version\ThesisProject2\dicom_server\core\dicomdb.py", line 119, in query_series_level
    matchedInstances = db.search(
                       ^^^^^^^^^^
  File "C:\Users\45422\Desktop\API_version\ThesisProject2\dicom_server\core\db.py", line 475, in search
    return _search_qr(model, identifier, session)
           ^^^^^^^^^^^^^^^^^^^^^^^^^^^^^^^^^^^^^^
  File "C:\Users\45422\Desktop\API_version\ThesisProject2\dicom_server\core\db.py", line 497, in _search_qr
    _check_identifier(identifier, model)
  File "C:\Users\45422\Desktop\API_version\ThesisProject2\dicom_server\core\db.py", line 375, in _check_identifier
    raise InvalidIdentifier(
db.InvalidIdentifier: The Identifier is missing a unique key for the 'STUDY' level

Exception at 25-02-2025 : 10-48-34
.............................................
In db
Message: Exception in handling C-FIND operation
Traceback :
 ............
Traceback (most recent call last):
  File "C:\Users\45422\Desktop\API_version\ThesisProject2\dicom_server\core\dicom_handlers.py", line 118, in handle_find
    matches = self.dicomdb.query_series_level(identifier)
              ^^^^^^^^^^^^^^^^^^^^^^^^^^^^^^^^^^^^^^^^^^^
  File "C:\Users\45422\Desktop\API_version\ThesisProject2\dicom_server\core\dicomdb.py", line 119, in query_series_level
    matchedInstances = db.search(
                       ^^^^^^^^^^
  File "C:\Users\45422\Desktop\API_version\ThesisProject2\dicom_server\core\db.py", line 475, in search
    return _search_qr(model, identifier, session)
           ^^^^^^^^^^^^^^^^^^^^^^^^^^^^^^^^^^^^^^
  File "C:\Users\45422\Desktop\API_version\ThesisProject2\dicom_server\core\db.py", line 497, in _search_qr
    _check_identifier(identifier, model)
  File "C:\Users\45422\Desktop\API_version\ThesisProject2\dicom_server\core\db.py", line 375, in _check_identifier
    raise InvalidIdentifier(
db.InvalidIdentifier: The Identifier is missing a unique key for the 'STUDY' level

Exception at 25-02-2025 : 10-53-37
.............................................
In db
Message: Exception in SERIES level query
Traceback :
 ............
Traceback (most recent call last):
  File "C:\Users\45422\Desktop\API_version\ThesisProject2\dicom_server\core\dicomdb.py", line 119, in query_series_level
    matchedInstances = db.search(
                       ^^^^^^^^^^
  File "C:\Users\45422\Desktop\API_version\ThesisProject2\dicom_server\core\db.py", line 475, in search
    return _search_qr(model, identifier, session)
           ^^^^^^^^^^^^^^^^^^^^^^^^^^^^^^^^^^^^^^
  File "C:\Users\45422\Desktop\API_version\ThesisProject2\dicom_server\core\db.py", line 497, in _search_qr
    _check_identifier(identifier, model)
  File "C:\Users\45422\Desktop\API_version\ThesisProject2\dicom_server\core\db.py", line 375, in _check_identifier
    raise InvalidIdentifier(
db.InvalidIdentifier: The Identifier is missing a unique key for the 'STUDY' level

Exception at 25-02-2025 : 10-53-37
.............................................
In db
Message: Exception in handling C-FIND operation
Traceback :
 ............
Traceback (most recent call last):
  File "C:\Users\45422\Desktop\API_version\ThesisProject2\dicom_server\core\dicom_handlers.py", line 118, in handle_find
    matches = self.dicomdb.query_series_level(identifier)
              ^^^^^^^^^^^^^^^^^^^^^^^^^^^^^^^^^^^^^^^^^^^
  File "C:\Users\45422\Desktop\API_version\ThesisProject2\dicom_server\core\dicomdb.py", line 119, in query_series_level
    matchedInstances = db.search(
                       ^^^^^^^^^^
  File "C:\Users\45422\Desktop\API_version\ThesisProject2\dicom_server\core\db.py", line 475, in search
    return _search_qr(model, identifier, session)
           ^^^^^^^^^^^^^^^^^^^^^^^^^^^^^^^^^^^^^^
  File "C:\Users\45422\Desktop\API_version\ThesisProject2\dicom_server\core\db.py", line 497, in _search_qr
    _check_identifier(identifier, model)
  File "C:\Users\45422\Desktop\API_version\ThesisProject2\dicom_server\core\db.py", line 375, in _check_identifier
    raise InvalidIdentifier(
db.InvalidIdentifier: The Identifier is missing a unique key for the 'STUDY' level

Exception at 25-02-2025 : 10-54-12
.............................................
In db
Message: Exception in SERIES level query
Traceback :
 ............
Traceback (most recent call last):
  File "C:\Users\45422\Desktop\API_version\ThesisProject2\dicom_server\core\dicomdb.py", line 119, in query_series_level
    matchedInstances = db.search(
                       ^^^^^^^^^^
  File "C:\Users\45422\Desktop\API_version\ThesisProject2\dicom_server\core\db.py", line 475, in search
    return _search_qr(model, identifier, session)
           ^^^^^^^^^^^^^^^^^^^^^^^^^^^^^^^^^^^^^^
  File "C:\Users\45422\Desktop\API_version\ThesisProject2\dicom_server\core\db.py", line 497, in _search_qr
    _check_identifier(identifier, model)
  File "C:\Users\45422\Desktop\API_version\ThesisProject2\dicom_server\core\db.py", line 375, in _check_identifier
    raise InvalidIdentifier(
db.InvalidIdentifier: The Identifier is missing a unique key for the 'STUDY' level

Exception at 25-02-2025 : 10-54-12
.............................................
In db
Message: Exception in handling C-FIND operation
Traceback :
 ............
Traceback (most recent call last):
  File "C:\Users\45422\Desktop\API_version\ThesisProject2\dicom_server\core\dicom_handlers.py", line 118, in handle_find
    matches = self.dicomdb.query_series_level(identifier)
              ^^^^^^^^^^^^^^^^^^^^^^^^^^^^^^^^^^^^^^^^^^^
  File "C:\Users\45422\Desktop\API_version\ThesisProject2\dicom_server\core\dicomdb.py", line 119, in query_series_level
    matchedInstances = db.search(
                       ^^^^^^^^^^
  File "C:\Users\45422\Desktop\API_version\ThesisProject2\dicom_server\core\db.py", line 475, in search
    return _search_qr(model, identifier, session)
           ^^^^^^^^^^^^^^^^^^^^^^^^^^^^^^^^^^^^^^
  File "C:\Users\45422\Desktop\API_version\ThesisProject2\dicom_server\core\db.py", line 497, in _search_qr
    _check_identifier(identifier, model)
  File "C:\Users\45422\Desktop\API_version\ThesisProject2\dicom_server\core\db.py", line 375, in _check_identifier
    raise InvalidIdentifier(
db.InvalidIdentifier: The Identifier is missing a unique key for the 'STUDY' level

Exception at 25-02-2025 : 10-55-09
.............................................
In db
Message: Exception in PATIENT level query
Traceback :
 ............
Traceback (most recent call last):
  File "C:\Users\45422\Desktop\API_version\ThesisProject2\dicom_server\core\dicomdb.py", line 137, in query_patient_level
    matchedInstances = db.search(
                       ^^^^^^^^^^
  File "C:\Users\45422\Desktop\API_version\ThesisProject2\dicom_server\core\db.py", line 475, in search
    return _search_qr(model, identifier, session)
           ^^^^^^^^^^^^^^^^^^^^^^^^^^^^^^^^^^^^^^
  File "C:\Users\45422\Desktop\API_version\ThesisProject2\dicom_server\core\db.py", line 517, in _search_qr
    return query.all()
           ^^^^^^^^^
AttributeError: 'NoneType' object has no attribute 'all'

Exception at 25-02-2025 : 10-55-09
.............................................
In db
Message: Exception in handling C-FIND operation
Traceback :
 ............
Traceback (most recent call last):
  File "C:\Users\45422\Desktop\API_version\ThesisProject2\dicom_server\core\dicom_handlers.py", line 114, in handle_find
    matches = self.dicomdb.query_patient_level(identifier)
              ^^^^^^^^^^^^^^^^^^^^^^^^^^^^^^^^^^^^^^^^^^^^
  File "C:\Users\45422\Desktop\API_version\ThesisProject2\dicom_server\core\dicomdb.py", line 137, in query_patient_level
    matchedInstances = db.search(
                       ^^^^^^^^^^
  File "C:\Users\45422\Desktop\API_version\ThesisProject2\dicom_server\core\db.py", line 475, in search
    return _search_qr(model, identifier, session)
           ^^^^^^^^^^^^^^^^^^^^^^^^^^^^^^^^^^^^^^
  File "C:\Users\45422\Desktop\API_version\ThesisProject2\dicom_server\core\db.py", line 517, in _search_qr
    return query.all()
           ^^^^^^^^^
AttributeError: 'NoneType' object has no attribute 'all'

Exception at 25-02-2025 : 10-55-24
.............................................
In db
Message: Exception in PATIENT level query
Traceback :
 ............
Traceback (most recent call last):
  File "C:\Users\45422\Desktop\API_version\ThesisProject2\dicom_server\core\dicomdb.py", line 137, in query_patient_level
    matchedInstances = db.search(
                       ^^^^^^^^^^
  File "C:\Users\45422\Desktop\API_version\ThesisProject2\dicom_server\core\db.py", line 475, in search
    return _search_qr(model, identifier, session)
           ^^^^^^^^^^^^^^^^^^^^^^^^^^^^^^^^^^^^^^
  File "C:\Users\45422\Desktop\API_version\ThesisProject2\dicom_server\core\db.py", line 517, in _search_qr
    return query.all()
           ^^^^^^^^^
AttributeError: 'NoneType' object has no attribute 'all'

Exception at 25-02-2025 : 10-55-24
.............................................
In db
Message: Exception in handling C-FIND operation
Traceback :
 ............
Traceback (most recent call last):
  File "C:\Users\45422\Desktop\API_version\ThesisProject2\dicom_server\core\dicom_handlers.py", line 114, in handle_find
    matches = self.dicomdb.query_patient_level(identifier)
              ^^^^^^^^^^^^^^^^^^^^^^^^^^^^^^^^^^^^^^^^^^^^
  File "C:\Users\45422\Desktop\API_version\ThesisProject2\dicom_server\core\dicomdb.py", line 137, in query_patient_level
    matchedInstances = db.search(
                       ^^^^^^^^^^
  File "C:\Users\45422\Desktop\API_version\ThesisProject2\dicom_server\core\db.py", line 475, in search
    return _search_qr(model, identifier, session)
           ^^^^^^^^^^^^^^^^^^^^^^^^^^^^^^^^^^^^^^
  File "C:\Users\45422\Desktop\API_version\ThesisProject2\dicom_server\core\db.py", line 517, in _search_qr
    return query.all()
           ^^^^^^^^^
AttributeError: 'NoneType' object has no attribute 'all'

Exception at 25-02-2025 : 11-50-26
.............................................
In db
Message: Exception in SERIES level query
Traceback :
 ............
Traceback (most recent call last):
  File "C:\Users\45422\Desktop\API_version\ThesisProject2\dicom_server\core\dicomdb.py", line 119, in query_series_level
    matchedInstances = db.search(
                       ^^^^^^^^^^
  File "C:\Users\45422\Desktop\API_version\ThesisProject2\dicom_server\core\db.py", line 475, in search
    return _search_qr(model, identifier, session)
           ^^^^^^^^^^^^^^^^^^^^^^^^^^^^^^^^^^^^^^
  File "C:\Users\45422\Desktop\API_version\ThesisProject2\dicom_server\core\db.py", line 497, in _search_qr
    _check_identifier(identifier, model)
  File "C:\Users\45422\Desktop\API_version\ThesisProject2\dicom_server\core\db.py", line 375, in _check_identifier
    raise InvalidIdentifier(
db.InvalidIdentifier: The Identifier is missing a unique key for the 'STUDY' level

Exception at 25-02-2025 : 11-50-26
.............................................
In db
Message: Exception in handling C-FIND operation
Traceback :
 ............
Traceback (most recent call last):
  File "C:\Users\45422\Desktop\API_version\ThesisProject2\dicom_server\core\dicom_handlers.py", line 118, in handle_find
    matches = self.dicomdb.query_series_level(identifier)
              ^^^^^^^^^^^^^^^^^^^^^^^^^^^^^^^^^^^^^^^^^^^
  File "C:\Users\45422\Desktop\API_version\ThesisProject2\dicom_server\core\dicomdb.py", line 119, in query_series_level
    matchedInstances = db.search(
                       ^^^^^^^^^^
  File "C:\Users\45422\Desktop\API_version\ThesisProject2\dicom_server\core\db.py", line 475, in search
    return _search_qr(model, identifier, session)
           ^^^^^^^^^^^^^^^^^^^^^^^^^^^^^^^^^^^^^^
  File "C:\Users\45422\Desktop\API_version\ThesisProject2\dicom_server\core\db.py", line 497, in _search_qr
    _check_identifier(identifier, model)
  File "C:\Users\45422\Desktop\API_version\ThesisProject2\dicom_server\core\db.py", line 375, in _check_identifier
    raise InvalidIdentifier(
db.InvalidIdentifier: The Identifier is missing a unique key for the 'STUDY' level

Exception at 25-02-2025 : 12-56-56
.............................................
In dicomdb
Message: Exception while getting series data sets
Traceback :
 ............
Traceback (most recent call last):
  File "C:\Users\45422\Desktop\API_version\ThesisProject2\dicom_server\core\dicomdb.py", line 188, in get_seriesRoot_dataset
    "SERIES", "patient_name", getattr(instance, "series_instance_uid")
                              ^^^^^^^^^^^^^^^^^^^^^^^^^^^^^^^^^^^^^^^^
AttributeError: 'Study' object has no attribute 'series_instance_uid'

Exception at 25-02-2025 : 12-56-56
.............................................
In dicomdb
Message: Exception while getting series data sets
Traceback :
 ............
Traceback (most recent call last):
  File "C:\Users\45422\Desktop\API_version\ThesisProject2\dicom_server\core\dicomdb.py", line 188, in get_seriesRoot_dataset
    "SERIES", "patient_name", getattr(instance, "series_instance_uid")
                              ^^^^^^^^^^^^^^^^^^^^^^^^^^^^^^^^^^^^^^^^
AttributeError: 'Study' object has no attribute 'series_instance_uid'

Exception at 25-02-2025 : 12-56-56
.............................................
In dicomdb
Message: Exception while getting series data sets
Traceback :
 ............
Traceback (most recent call last):
  File "C:\Users\45422\Desktop\API_version\ThesisProject2\dicom_server\core\dicomdb.py", line 188, in get_seriesRoot_dataset
    "SERIES", "patient_name", getattr(instance, "series_instance_uid")
                              ^^^^^^^^^^^^^^^^^^^^^^^^^^^^^^^^^^^^^^^^
AttributeError: 'Study' object has no attribute 'series_instance_uid'

Exception at 25-02-2025 : 12-56-56
.............................................
In dicomdb
Message: Exception while getting series data sets
Traceback :
 ............
Traceback (most recent call last):
  File "C:\Users\45422\Desktop\API_version\ThesisProject2\dicom_server\core\dicomdb.py", line 188, in get_seriesRoot_dataset
    "SERIES", "patient_name", getattr(instance, "series_instance_uid")
                              ^^^^^^^^^^^^^^^^^^^^^^^^^^^^^^^^^^^^^^^^
AttributeError: 'Study' object has no attribute 'series_instance_uid'

Exception at 25-02-2025 : 12-56-56
.............................................
In dicomdb
Message: Exception while getting series data sets
Traceback :
 ............
Traceback (most recent call last):
  File "C:\Users\45422\Desktop\API_version\ThesisProject2\dicom_server\core\dicomdb.py", line 188, in get_seriesRoot_dataset
    "SERIES", "patient_name", getattr(instance, "series_instance_uid")
                              ^^^^^^^^^^^^^^^^^^^^^^^^^^^^^^^^^^^^^^^^
AttributeError: 'Study' object has no attribute 'series_instance_uid'

Exception at 25-02-2025 : 12-56-56
.............................................
In dicomdb
Message: Exception while getting series data sets
Traceback :
 ............
Traceback (most recent call last):
  File "C:\Users\45422\Desktop\API_version\ThesisProject2\dicom_server\core\dicomdb.py", line 188, in get_seriesRoot_dataset
    "SERIES", "patient_name", getattr(instance, "series_instance_uid")
                              ^^^^^^^^^^^^^^^^^^^^^^^^^^^^^^^^^^^^^^^^
AttributeError: 'Study' object has no attribute 'series_instance_uid'

Exception at 25-02-2025 : 12-56-56
.............................................
In dicomdb
Message: Exception while getting series data sets
Traceback :
 ............
Traceback (most recent call last):
  File "C:\Users\45422\Desktop\API_version\ThesisProject2\dicom_server\core\dicomdb.py", line 188, in get_seriesRoot_dataset
    "SERIES", "patient_name", getattr(instance, "series_instance_uid")
                              ^^^^^^^^^^^^^^^^^^^^^^^^^^^^^^^^^^^^^^^^
AttributeError: 'Study' object has no attribute 'series_instance_uid'

Exception at 25-02-2025 : 12-56-56
.............................................
In dicomdb
Message: Exception while getting series data sets
Traceback :
 ............
Traceback (most recent call last):
  File "C:\Users\45422\Desktop\API_version\ThesisProject2\dicom_server\core\dicomdb.py", line 188, in get_seriesRoot_dataset
    "SERIES", "patient_name", getattr(instance, "series_instance_uid")
                              ^^^^^^^^^^^^^^^^^^^^^^^^^^^^^^^^^^^^^^^^
AttributeError: 'Study' object has no attribute 'series_instance_uid'

Exception at 25-02-2025 : 12-56-56
.............................................
In dicomdb
Message: Exception while getting series data sets
Traceback :
 ............
Traceback (most recent call last):
  File "C:\Users\45422\Desktop\API_version\ThesisProject2\dicom_server\core\dicomdb.py", line 188, in get_seriesRoot_dataset
    "SERIES", "patient_name", getattr(instance, "series_instance_uid")
                              ^^^^^^^^^^^^^^^^^^^^^^^^^^^^^^^^^^^^^^^^
AttributeError: 'Study' object has no attribute 'series_instance_uid'

Exception at 25-02-2025 : 12-56-56
.............................................
In dicomdb
Message: Exception while getting series data sets
Traceback :
 ............
Traceback (most recent call last):
  File "C:\Users\45422\Desktop\API_version\ThesisProject2\dicom_server\core\dicomdb.py", line 188, in get_seriesRoot_dataset
    "SERIES", "patient_name", getattr(instance, "series_instance_uid")
                              ^^^^^^^^^^^^^^^^^^^^^^^^^^^^^^^^^^^^^^^^
AttributeError: 'Study' object has no attribute 'series_instance_uid'

Exception at 25-02-2025 : 12-56-56
.............................................
In dicomdb
Message: Exception while getting series data sets
Traceback :
 ............
Traceback (most recent call last):
  File "C:\Users\45422\Desktop\API_version\ThesisProject2\dicom_server\core\dicomdb.py", line 188, in get_seriesRoot_dataset
    "SERIES", "patient_name", getattr(instance, "series_instance_uid")
                              ^^^^^^^^^^^^^^^^^^^^^^^^^^^^^^^^^^^^^^^^
AttributeError: 'Study' object has no attribute 'series_instance_uid'

Exception at 25-02-2025 : 12-56-56
.............................................
In dicomdb
Message: Exception while getting series data sets
Traceback :
 ............
Traceback (most recent call last):
  File "C:\Users\45422\Desktop\API_version\ThesisProject2\dicom_server\core\dicomdb.py", line 188, in get_seriesRoot_dataset
    "SERIES", "patient_name", getattr(instance, "series_instance_uid")
                              ^^^^^^^^^^^^^^^^^^^^^^^^^^^^^^^^^^^^^^^^
AttributeError: 'Study' object has no attribute 'series_instance_uid'

Exception at 25-02-2025 : 12-56-56
.............................................
In dicomdb
Message: Exception while getting series data sets
Traceback :
 ............
Traceback (most recent call last):
  File "C:\Users\45422\Desktop\API_version\ThesisProject2\dicom_server\core\dicomdb.py", line 188, in get_seriesRoot_dataset
    "SERIES", "patient_name", getattr(instance, "series_instance_uid")
                              ^^^^^^^^^^^^^^^^^^^^^^^^^^^^^^^^^^^^^^^^
AttributeError: 'Study' object has no attribute 'series_instance_uid'

Exception at 25-02-2025 : 12-56-56
.............................................
In dicomdb
Message: Exception while getting series data sets
Traceback :
 ............
Traceback (most recent call last):
  File "C:\Users\45422\Desktop\API_version\ThesisProject2\dicom_server\core\dicomdb.py", line 188, in get_seriesRoot_dataset
    "SERIES", "patient_name", getattr(instance, "series_instance_uid")
                              ^^^^^^^^^^^^^^^^^^^^^^^^^^^^^^^^^^^^^^^^
AttributeError: 'Study' object has no attribute 'series_instance_uid'

Exception at 25-02-2025 : 12-56-56
.............................................
In dicomdb
Message: Exception while getting series data sets
Traceback :
 ............
Traceback (most recent call last):
  File "C:\Users\45422\Desktop\API_version\ThesisProject2\dicom_server\core\dicomdb.py", line 188, in get_seriesRoot_dataset
    "SERIES", "patient_name", getattr(instance, "series_instance_uid")
                              ^^^^^^^^^^^^^^^^^^^^^^^^^^^^^^^^^^^^^^^^
AttributeError: 'Study' object has no attribute 'series_instance_uid'

Exception at 25-02-2025 : 12-56-56
.............................................
In dicomdb
Message: Exception while getting series data sets
Traceback :
 ............
Traceback (most recent call last):
  File "C:\Users\45422\Desktop\API_version\ThesisProject2\dicom_server\core\dicomdb.py", line 188, in get_seriesRoot_dataset
    "SERIES", "patient_name", getattr(instance, "series_instance_uid")
                              ^^^^^^^^^^^^^^^^^^^^^^^^^^^^^^^^^^^^^^^^
AttributeError: 'Study' object has no attribute 'series_instance_uid'

Exception at 25-02-2025 : 12-56-56
.............................................
In dicomdb
Message: Exception while getting series data sets
Traceback :
 ............
Traceback (most recent call last):
  File "C:\Users\45422\Desktop\API_version\ThesisProject2\dicom_server\core\dicomdb.py", line 188, in get_seriesRoot_dataset
    "SERIES", "patient_name", getattr(instance, "series_instance_uid")
                              ^^^^^^^^^^^^^^^^^^^^^^^^^^^^^^^^^^^^^^^^
AttributeError: 'Study' object has no attribute 'series_instance_uid'

Exception at 25-02-2025 : 12-56-56
.............................................
In dicomdb
Message: Exception while getting series data sets
Traceback :
 ............
Traceback (most recent call last):
  File "C:\Users\45422\Desktop\API_version\ThesisProject2\dicom_server\core\dicomdb.py", line 188, in get_seriesRoot_dataset
    "SERIES", "patient_name", getattr(instance, "series_instance_uid")
                              ^^^^^^^^^^^^^^^^^^^^^^^^^^^^^^^^^^^^^^^^
AttributeError: 'Study' object has no attribute 'series_instance_uid'

Exception at 25-02-2025 : 12-56-56
.............................................
In dicomdb
Message: Exception while getting series data sets
Traceback :
 ............
Traceback (most recent call last):
  File "C:\Users\45422\Desktop\API_version\ThesisProject2\dicom_server\core\dicomdb.py", line 188, in get_seriesRoot_dataset
    "SERIES", "patient_name", getattr(instance, "series_instance_uid")
                              ^^^^^^^^^^^^^^^^^^^^^^^^^^^^^^^^^^^^^^^^
AttributeError: 'Study' object has no attribute 'series_instance_uid'

Exception at 25-02-2025 : 12-56-56
.............................................
In dicomdb
Message: Exception while getting series data sets
Traceback :
 ............
Traceback (most recent call last):
  File "C:\Users\45422\Desktop\API_version\ThesisProject2\dicom_server\core\dicomdb.py", line 188, in get_seriesRoot_dataset
    "SERIES", "patient_name", getattr(instance, "series_instance_uid")
                              ^^^^^^^^^^^^^^^^^^^^^^^^^^^^^^^^^^^^^^^^
AttributeError: 'Study' object has no attribute 'series_instance_uid'

Exception at 25-02-2025 : 12-56-57
.............................................
In dicomdb
Message: Exception while getting series data sets
Traceback :
 ............
Traceback (most recent call last):
  File "C:\Users\45422\Desktop\API_version\ThesisProject2\dicom_server\core\dicomdb.py", line 188, in get_seriesRoot_dataset
    "SERIES", "patient_name", getattr(instance, "series_instance_uid")
                              ^^^^^^^^^^^^^^^^^^^^^^^^^^^^^^^^^^^^^^^^
AttributeError: 'Study' object has no attribute 'series_instance_uid'

Exception at 25-02-2025 : 12-56-57
.............................................
In dicomdb
Message: Exception while getting series data sets
Traceback :
 ............
Traceback (most recent call last):
  File "C:\Users\45422\Desktop\API_version\ThesisProject2\dicom_server\core\dicomdb.py", line 188, in get_seriesRoot_dataset
    "SERIES", "patient_name", getattr(instance, "series_instance_uid")
                              ^^^^^^^^^^^^^^^^^^^^^^^^^^^^^^^^^^^^^^^^
AttributeError: 'Study' object has no attribute 'series_instance_uid'

Exception at 25-02-2025 : 12-56-57
.............................................
In dicomdb
Message: Exception while getting series data sets
Traceback :
 ............
Traceback (most recent call last):
  File "C:\Users\45422\Desktop\API_version\ThesisProject2\dicom_server\core\dicomdb.py", line 188, in get_seriesRoot_dataset
    "SERIES", "patient_name", getattr(instance, "series_instance_uid")
                              ^^^^^^^^^^^^^^^^^^^^^^^^^^^^^^^^^^^^^^^^
AttributeError: 'Study' object has no attribute 'series_instance_uid'

Exception at 25-02-2025 : 12-56-57
.............................................
In dicomdb
Message: Exception while getting series data sets
Traceback :
 ............
Traceback (most recent call last):
  File "C:\Users\45422\Desktop\API_version\ThesisProject2\dicom_server\core\dicomdb.py", line 188, in get_seriesRoot_dataset
    "SERIES", "patient_name", getattr(instance, "series_instance_uid")
                              ^^^^^^^^^^^^^^^^^^^^^^^^^^^^^^^^^^^^^^^^
AttributeError: 'Study' object has no attribute 'series_instance_uid'

Exception at 25-02-2025 : 12-56-57
.............................................
In dicomdb
Message: Exception while getting series data sets
Traceback :
 ............
Traceback (most recent call last):
  File "C:\Users\45422\Desktop\API_version\ThesisProject2\dicom_server\core\dicomdb.py", line 188, in get_seriesRoot_dataset
    "SERIES", "patient_name", getattr(instance, "series_instance_uid")
                              ^^^^^^^^^^^^^^^^^^^^^^^^^^^^^^^^^^^^^^^^
AttributeError: 'Study' object has no attribute 'series_instance_uid'

Exception at 25-02-2025 : 12-56-57
.............................................
In dicomdb
Message: Exception while getting series data sets
Traceback :
 ............
Traceback (most recent call last):
  File "C:\Users\45422\Desktop\API_version\ThesisProject2\dicom_server\core\dicomdb.py", line 188, in get_seriesRoot_dataset
    "SERIES", "patient_name", getattr(instance, "series_instance_uid")
                              ^^^^^^^^^^^^^^^^^^^^^^^^^^^^^^^^^^^^^^^^
AttributeError: 'Study' object has no attribute 'series_instance_uid'

Exception at 25-02-2025 : 12-56-57
.............................................
In dicomdb
Message: Exception while getting series data sets
Traceback :
 ............
Traceback (most recent call last):
  File "C:\Users\45422\Desktop\API_version\ThesisProject2\dicom_server\core\dicomdb.py", line 188, in get_seriesRoot_dataset
    "SERIES", "patient_name", getattr(instance, "series_instance_uid")
                              ^^^^^^^^^^^^^^^^^^^^^^^^^^^^^^^^^^^^^^^^
AttributeError: 'Study' object has no attribute 'series_instance_uid'

Exception at 25-02-2025 : 12-56-57
.............................................
In dicomdb
Message: Exception while getting series data sets
Traceback :
 ............
Traceback (most recent call last):
  File "C:\Users\45422\Desktop\API_version\ThesisProject2\dicom_server\core\dicomdb.py", line 188, in get_seriesRoot_dataset
    "SERIES", "patient_name", getattr(instance, "series_instance_uid")
                              ^^^^^^^^^^^^^^^^^^^^^^^^^^^^^^^^^^^^^^^^
AttributeError: 'Study' object has no attribute 'series_instance_uid'

Exception at 25-02-2025 : 12-56-57
.............................................
In dicomdb
Message: Exception while getting series data sets
Traceback :
 ............
Traceback (most recent call last):
  File "C:\Users\45422\Desktop\API_version\ThesisProject2\dicom_server\core\dicomdb.py", line 188, in get_seriesRoot_dataset
    "SERIES", "patient_name", getattr(instance, "series_instance_uid")
                              ^^^^^^^^^^^^^^^^^^^^^^^^^^^^^^^^^^^^^^^^
AttributeError: 'Study' object has no attribute 'series_instance_uid'

Exception at 25-02-2025 : 12-56-57
.............................................
In dicomdb
Message: Exception while getting series data sets
Traceback :
 ............
Traceback (most recent call last):
  File "C:\Users\45422\Desktop\API_version\ThesisProject2\dicom_server\core\dicomdb.py", line 188, in get_seriesRoot_dataset
    "SERIES", "patient_name", getattr(instance, "series_instance_uid")
                              ^^^^^^^^^^^^^^^^^^^^^^^^^^^^^^^^^^^^^^^^
AttributeError: 'Study' object has no attribute 'series_instance_uid'

Exception at 25-02-2025 : 12-56-57
.............................................
In dicomdb
Message: Exception while getting series data sets
Traceback :
 ............
Traceback (most recent call last):
  File "C:\Users\45422\Desktop\API_version\ThesisProject2\dicom_server\core\dicomdb.py", line 188, in get_seriesRoot_dataset
    "SERIES", "patient_name", getattr(instance, "series_instance_uid")
                              ^^^^^^^^^^^^^^^^^^^^^^^^^^^^^^^^^^^^^^^^
AttributeError: 'Study' object has no attribute 'series_instance_uid'

Exception at 25-02-2025 : 12-56-57
.............................................
In dicomdb
Message: Exception while getting series data sets
Traceback :
 ............
Traceback (most recent call last):
  File "C:\Users\45422\Desktop\API_version\ThesisProject2\dicom_server\core\dicomdb.py", line 188, in get_seriesRoot_dataset
    "SERIES", "patient_name", getattr(instance, "series_instance_uid")
                              ^^^^^^^^^^^^^^^^^^^^^^^^^^^^^^^^^^^^^^^^
AttributeError: 'Study' object has no attribute 'series_instance_uid'

Exception at 25-02-2025 : 12-56-57
.............................................
In dicomdb
Message: Exception while getting series data sets
Traceback :
 ............
Traceback (most recent call last):
  File "C:\Users\45422\Desktop\API_version\ThesisProject2\dicom_server\core\dicomdb.py", line 188, in get_seriesRoot_dataset
    "SERIES", "patient_name", getattr(instance, "series_instance_uid")
                              ^^^^^^^^^^^^^^^^^^^^^^^^^^^^^^^^^^^^^^^^
AttributeError: 'Study' object has no attribute 'series_instance_uid'

Exception at 25-02-2025 : 12-56-57
.............................................
In dicomdb
Message: Exception while getting series data sets
Traceback :
 ............
Traceback (most recent call last):
  File "C:\Users\45422\Desktop\API_version\ThesisProject2\dicom_server\core\dicomdb.py", line 188, in get_seriesRoot_dataset
    "SERIES", "patient_name", getattr(instance, "series_instance_uid")
                              ^^^^^^^^^^^^^^^^^^^^^^^^^^^^^^^^^^^^^^^^
AttributeError: 'Study' object has no attribute 'series_instance_uid'

Exception at 25-02-2025 : 12-56-57
.............................................
In dicomdb
Message: Exception while getting series data sets
Traceback :
 ............
Traceback (most recent call last):
  File "C:\Users\45422\Desktop\API_version\ThesisProject2\dicom_server\core\dicomdb.py", line 188, in get_seriesRoot_dataset
    "SERIES", "patient_name", getattr(instance, "series_instance_uid")
                              ^^^^^^^^^^^^^^^^^^^^^^^^^^^^^^^^^^^^^^^^
AttributeError: 'Study' object has no attribute 'series_instance_uid'

Exception at 25-02-2025 : 12-56-57
.............................................
In dicomdb
Message: Exception while getting series data sets
Traceback :
 ............
Traceback (most recent call last):
  File "C:\Users\45422\Desktop\API_version\ThesisProject2\dicom_server\core\dicomdb.py", line 188, in get_seriesRoot_dataset
    "SERIES", "patient_name", getattr(instance, "series_instance_uid")
                              ^^^^^^^^^^^^^^^^^^^^^^^^^^^^^^^^^^^^^^^^
AttributeError: 'Study' object has no attribute 'series_instance_uid'

Exception at 25-02-2025 : 12-56-57
.............................................
In dicomdb
Message: Exception while getting series data sets
Traceback :
 ............
Traceback (most recent call last):
  File "C:\Users\45422\Desktop\API_version\ThesisProject2\dicom_server\core\dicomdb.py", line 188, in get_seriesRoot_dataset
    "SERIES", "patient_name", getattr(instance, "series_instance_uid")
                              ^^^^^^^^^^^^^^^^^^^^^^^^^^^^^^^^^^^^^^^^
AttributeError: 'Study' object has no attribute 'series_instance_uid'

Exception at 25-02-2025 : 12-56-57
.............................................
In dicomdb
Message: Exception while getting series data sets
Traceback :
 ............
Traceback (most recent call last):
  File "C:\Users\45422\Desktop\API_version\ThesisProject2\dicom_server\core\dicomdb.py", line 188, in get_seriesRoot_dataset
    "SERIES", "patient_name", getattr(instance, "series_instance_uid")
                              ^^^^^^^^^^^^^^^^^^^^^^^^^^^^^^^^^^^^^^^^
AttributeError: 'Study' object has no attribute 'series_instance_uid'

Exception at 25-02-2025 : 12-56-57
.............................................
In dicomdb
Message: Exception while getting series data sets
Traceback :
 ............
Traceback (most recent call last):
  File "C:\Users\45422\Desktop\API_version\ThesisProject2\dicom_server\core\dicomdb.py", line 188, in get_seriesRoot_dataset
    "SERIES", "patient_name", getattr(instance, "series_instance_uid")
                              ^^^^^^^^^^^^^^^^^^^^^^^^^^^^^^^^^^^^^^^^
AttributeError: 'Study' object has no attribute 'series_instance_uid'

Exception at 25-02-2025 : 12-56-57
.............................................
In dicomdb
Message: Exception while getting series data sets
Traceback :
 ............
Traceback (most recent call last):
  File "C:\Users\45422\Desktop\API_version\ThesisProject2\dicom_server\core\dicomdb.py", line 188, in get_seriesRoot_dataset
    "SERIES", "patient_name", getattr(instance, "series_instance_uid")
                              ^^^^^^^^^^^^^^^^^^^^^^^^^^^^^^^^^^^^^^^^
AttributeError: 'Study' object has no attribute 'series_instance_uid'

Exception at 25-02-2025 : 12-56-57
.............................................
In dicomdb
Message: Exception while getting series data sets
Traceback :
 ............
Traceback (most recent call last):
  File "C:\Users\45422\Desktop\API_version\ThesisProject2\dicom_server\core\dicomdb.py", line 188, in get_seriesRoot_dataset
    "SERIES", "patient_name", getattr(instance, "series_instance_uid")
                              ^^^^^^^^^^^^^^^^^^^^^^^^^^^^^^^^^^^^^^^^
AttributeError: 'Study' object has no attribute 'series_instance_uid'

Exception at 25-02-2025 : 12-58-21
.............................................
In db
Message: Exception in SERIES level query
Traceback :
 ............
Traceback (most recent call last):
  File "C:\Users\45422\Desktop\API_version\ThesisProject2\dicom_server\core\dicomdb.py", line 120, in query_series_level
    matchedInstances = db.search(
                       ^^^^^^^^^^
  File "C:\Users\45422\Desktop\API_version\ThesisProject2\dicom_server\core\db.py", line 475, in search
    return _search_qr(model, identifier, session)
           ^^^^^^^^^^^^^^^^^^^^^^^^^^^^^^^^^^^^^^
  File "C:\Users\45422\Desktop\API_version\ThesisProject2\dicom_server\core\db.py", line 497, in _search_qr
    _check_identifier(identifier, model)
  File "C:\Users\45422\Desktop\API_version\ThesisProject2\dicom_server\core\db.py", line 375, in _check_identifier
    raise InvalidIdentifier(
db.InvalidIdentifier: The Identifier is missing a unique key for the 'STUDY' level

Exception at 25-02-2025 : 12-58-21
.............................................
In db
Message: Exception in handling C-FIND operation
Traceback :
 ............
Traceback (most recent call last):
  File "C:\Users\45422\Desktop\API_version\ThesisProject2\dicom_server\core\dicom_handlers.py", line 118, in handle_find
    matches = self.dicomdb.query_series_level(identifier)
              ^^^^^^^^^^^^^^^^^^^^^^^^^^^^^^^^^^^^^^^^^^^
  File "C:\Users\45422\Desktop\API_version\ThesisProject2\dicom_server\core\dicomdb.py", line 120, in query_series_level
    matchedInstances = db.search(
                       ^^^^^^^^^^
  File "C:\Users\45422\Desktop\API_version\ThesisProject2\dicom_server\core\db.py", line 475, in search
    return _search_qr(model, identifier, session)
           ^^^^^^^^^^^^^^^^^^^^^^^^^^^^^^^^^^^^^^
  File "C:\Users\45422\Desktop\API_version\ThesisProject2\dicom_server\core\db.py", line 497, in _search_qr
    _check_identifier(identifier, model)
  File "C:\Users\45422\Desktop\API_version\ThesisProject2\dicom_server\core\db.py", line 375, in _check_identifier
    raise InvalidIdentifier(
db.InvalidIdentifier: The Identifier is missing a unique key for the 'STUDY' level

Exception at 25-02-2025 : 13-02-21
.............................................
In db
Message: Exception in SERIES level query
Traceback :
 ............
Traceback (most recent call last):
  File "C:\Users\45422\Desktop\API_version\ThesisProject2\dicom_server\core\dicomdb.py", line 120, in query_series_level
    matchedInstances = db.search(
                       ^^^^^^^^^^
  File "C:\Users\45422\Desktop\API_version\ThesisProject2\dicom_server\core\db.py", line 475, in search
    return _search_qr(model, identifier, session)
           ^^^^^^^^^^^^^^^^^^^^^^^^^^^^^^^^^^^^^^
  File "C:\Users\45422\Desktop\API_version\ThesisProject2\dicom_server\core\db.py", line 497, in _search_qr
    _check_identifier(identifier, model)
  File "C:\Users\45422\Desktop\API_version\ThesisProject2\dicom_server\core\db.py", line 375, in _check_identifier
    raise InvalidIdentifier(
db.InvalidIdentifier: The Identifier is missing a unique key for the 'STUDY' level

Exception at 25-02-2025 : 13-02-21
.............................................
In db
Message: Exception in handling C-FIND operation
Traceback :
 ............
Traceback (most recent call last):
  File "C:\Users\45422\Desktop\API_version\ThesisProject2\dicom_server\core\dicom_handlers.py", line 118, in handle_find
    matches = self.dicomdb.query_series_level(identifier)
              ^^^^^^^^^^^^^^^^^^^^^^^^^^^^^^^^^^^^^^^^^^^
  File "C:\Users\45422\Desktop\API_version\ThesisProject2\dicom_server\core\dicomdb.py", line 120, in query_series_level
    matchedInstances = db.search(
                       ^^^^^^^^^^
  File "C:\Users\45422\Desktop\API_version\ThesisProject2\dicom_server\core\db.py", line 475, in search
    return _search_qr(model, identifier, session)
           ^^^^^^^^^^^^^^^^^^^^^^^^^^^^^^^^^^^^^^
  File "C:\Users\45422\Desktop\API_version\ThesisProject2\dicom_server\core\db.py", line 497, in _search_qr
    _check_identifier(identifier, model)
  File "C:\Users\45422\Desktop\API_version\ThesisProject2\dicom_server\core\db.py", line 375, in _check_identifier
    raise InvalidIdentifier(
db.InvalidIdentifier: The Identifier is missing a unique key for the 'STUDY' level

Exception at 25-02-2025 : 13-07-08
.............................................
In dicomdb
Message: Exception while getting series data sets
Traceback :
 ............
Traceback (most recent call last):
  File "C:\Users\45422\Desktop\API_version\ThesisProject2\dicom_server\core\dicomdb.py", line 188, in get_seriesRoot_dataset
    "SERIES", "patient_name", getattr(instance, "series_instance_uid")
                              ^^^^^^^^^^^^^^^^^^^^^^^^^^^^^^^^^^^^^^^^
AttributeError: 'Study' object has no attribute 'series_instance_uid'

Exception at 25-02-2025 : 13-07-09
.............................................
In dicomdb
Message: Exception while getting series data sets
Traceback :
 ............
Traceback (most recent call last):
  File "C:\Users\45422\Desktop\API_version\ThesisProject2\dicom_server\core\dicomdb.py", line 188, in get_seriesRoot_dataset
    "SERIES", "patient_name", getattr(instance, "series_instance_uid")
                              ^^^^^^^^^^^^^^^^^^^^^^^^^^^^^^^^^^^^^^^^
AttributeError: 'Study' object has no attribute 'series_instance_uid'

Exception at 25-02-2025 : 13-07-09
.............................................
In dicomdb
Message: Exception while getting series data sets
Traceback :
 ............
Traceback (most recent call last):
  File "C:\Users\45422\Desktop\API_version\ThesisProject2\dicom_server\core\dicomdb.py", line 188, in get_seriesRoot_dataset
    "SERIES", "patient_name", getattr(instance, "series_instance_uid")
                              ^^^^^^^^^^^^^^^^^^^^^^^^^^^^^^^^^^^^^^^^
AttributeError: 'Study' object has no attribute 'series_instance_uid'

Exception at 25-02-2025 : 13-07-09
.............................................
In dicomdb
Message: Exception while getting series data sets
Traceback :
 ............
Traceback (most recent call last):
  File "C:\Users\45422\Desktop\API_version\ThesisProject2\dicom_server\core\dicomdb.py", line 188, in get_seriesRoot_dataset
    "SERIES", "patient_name", getattr(instance, "series_instance_uid")
                              ^^^^^^^^^^^^^^^^^^^^^^^^^^^^^^^^^^^^^^^^
AttributeError: 'Study' object has no attribute 'series_instance_uid'

Exception at 25-02-2025 : 13-07-09
.............................................
In dicomdb
Message: Exception while getting series data sets
Traceback :
 ............
Traceback (most recent call last):
  File "C:\Users\45422\Desktop\API_version\ThesisProject2\dicom_server\core\dicomdb.py", line 188, in get_seriesRoot_dataset
    "SERIES", "patient_name", getattr(instance, "series_instance_uid")
                              ^^^^^^^^^^^^^^^^^^^^^^^^^^^^^^^^^^^^^^^^
AttributeError: 'Study' object has no attribute 'series_instance_uid'

Exception at 25-02-2025 : 13-07-09
.............................................
In dicomdb
Message: Exception while getting series data sets
Traceback :
 ............
Traceback (most recent call last):
  File "C:\Users\45422\Desktop\API_version\ThesisProject2\dicom_server\core\dicomdb.py", line 188, in get_seriesRoot_dataset
    "SERIES", "patient_name", getattr(instance, "series_instance_uid")
                              ^^^^^^^^^^^^^^^^^^^^^^^^^^^^^^^^^^^^^^^^
AttributeError: 'Study' object has no attribute 'series_instance_uid'

Exception at 25-02-2025 : 13-07-09
.............................................
In dicomdb
Message: Exception while getting series data sets
Traceback :
 ............
Traceback (most recent call last):
  File "C:\Users\45422\Desktop\API_version\ThesisProject2\dicom_server\core\dicomdb.py", line 188, in get_seriesRoot_dataset
    "SERIES", "patient_name", getattr(instance, "series_instance_uid")
                              ^^^^^^^^^^^^^^^^^^^^^^^^^^^^^^^^^^^^^^^^
AttributeError: 'Study' object has no attribute 'series_instance_uid'

Exception at 25-02-2025 : 13-07-09
.............................................
In dicomdb
Message: Exception while getting series data sets
Traceback :
 ............
Traceback (most recent call last):
  File "C:\Users\45422\Desktop\API_version\ThesisProject2\dicom_server\core\dicomdb.py", line 188, in get_seriesRoot_dataset
    "SERIES", "patient_name", getattr(instance, "series_instance_uid")
                              ^^^^^^^^^^^^^^^^^^^^^^^^^^^^^^^^^^^^^^^^
AttributeError: 'Study' object has no attribute 'series_instance_uid'

Exception at 25-02-2025 : 13-07-09
.............................................
In dicomdb
Message: Exception while getting series data sets
Traceback :
 ............
Traceback (most recent call last):
  File "C:\Users\45422\Desktop\API_version\ThesisProject2\dicom_server\core\dicomdb.py", line 188, in get_seriesRoot_dataset
    "SERIES", "patient_name", getattr(instance, "series_instance_uid")
                              ^^^^^^^^^^^^^^^^^^^^^^^^^^^^^^^^^^^^^^^^
AttributeError: 'Study' object has no attribute 'series_instance_uid'

Exception at 25-02-2025 : 13-07-09
.............................................
In dicomdb
Message: Exception while getting series data sets
Traceback :
 ............
Traceback (most recent call last):
  File "C:\Users\45422\Desktop\API_version\ThesisProject2\dicom_server\core\dicomdb.py", line 188, in get_seriesRoot_dataset
    "SERIES", "patient_name", getattr(instance, "series_instance_uid")
                              ^^^^^^^^^^^^^^^^^^^^^^^^^^^^^^^^^^^^^^^^
AttributeError: 'Study' object has no attribute 'series_instance_uid'

Exception at 25-02-2025 : 13-07-09
.............................................
In dicomdb
Message: Exception while getting series data sets
Traceback :
 ............
Traceback (most recent call last):
  File "C:\Users\45422\Desktop\API_version\ThesisProject2\dicom_server\core\dicomdb.py", line 188, in get_seriesRoot_dataset
    "SERIES", "patient_name", getattr(instance, "series_instance_uid")
                              ^^^^^^^^^^^^^^^^^^^^^^^^^^^^^^^^^^^^^^^^
AttributeError: 'Study' object has no attribute 'series_instance_uid'

Exception at 25-02-2025 : 13-07-09
.............................................
In dicomdb
Message: Exception while getting series data sets
Traceback :
 ............
Traceback (most recent call last):
  File "C:\Users\45422\Desktop\API_version\ThesisProject2\dicom_server\core\dicomdb.py", line 188, in get_seriesRoot_dataset
    "SERIES", "patient_name", getattr(instance, "series_instance_uid")
                              ^^^^^^^^^^^^^^^^^^^^^^^^^^^^^^^^^^^^^^^^
AttributeError: 'Study' object has no attribute 'series_instance_uid'

Exception at 25-02-2025 : 13-07-09
.............................................
In dicomdb
Message: Exception while getting series data sets
Traceback :
 ............
Traceback (most recent call last):
  File "C:\Users\45422\Desktop\API_version\ThesisProject2\dicom_server\core\dicomdb.py", line 188, in get_seriesRoot_dataset
    "SERIES", "patient_name", getattr(instance, "series_instance_uid")
                              ^^^^^^^^^^^^^^^^^^^^^^^^^^^^^^^^^^^^^^^^
AttributeError: 'Study' object has no attribute 'series_instance_uid'

Exception at 25-02-2025 : 13-07-09
.............................................
In dicomdb
Message: Exception while getting series data sets
Traceback :
 ............
Traceback (most recent call last):
  File "C:\Users\45422\Desktop\API_version\ThesisProject2\dicom_server\core\dicomdb.py", line 188, in get_seriesRoot_dataset
    "SERIES", "patient_name", getattr(instance, "series_instance_uid")
                              ^^^^^^^^^^^^^^^^^^^^^^^^^^^^^^^^^^^^^^^^
AttributeError: 'Study' object has no attribute 'series_instance_uid'

Exception at 25-02-2025 : 13-07-09
.............................................
In dicomdb
Message: Exception while getting series data sets
Traceback :
 ............
Traceback (most recent call last):
  File "C:\Users\45422\Desktop\API_version\ThesisProject2\dicom_server\core\dicomdb.py", line 188, in get_seriesRoot_dataset
    "SERIES", "patient_name", getattr(instance, "series_instance_uid")
                              ^^^^^^^^^^^^^^^^^^^^^^^^^^^^^^^^^^^^^^^^
AttributeError: 'Study' object has no attribute 'series_instance_uid'

Exception at 25-02-2025 : 13-07-09
.............................................
In dicomdb
Message: Exception while getting series data sets
Traceback :
 ............
Traceback (most recent call last):
  File "C:\Users\45422\Desktop\API_version\ThesisProject2\dicom_server\core\dicomdb.py", line 188, in get_seriesRoot_dataset
    "SERIES", "patient_name", getattr(instance, "series_instance_uid")
                              ^^^^^^^^^^^^^^^^^^^^^^^^^^^^^^^^^^^^^^^^
AttributeError: 'Study' object has no attribute 'series_instance_uid'

Exception at 25-02-2025 : 13-07-09
.............................................
In dicomdb
Message: Exception while getting series data sets
Traceback :
 ............
Traceback (most recent call last):
  File "C:\Users\45422\Desktop\API_version\ThesisProject2\dicom_server\core\dicomdb.py", line 188, in get_seriesRoot_dataset
    "SERIES", "patient_name", getattr(instance, "series_instance_uid")
                              ^^^^^^^^^^^^^^^^^^^^^^^^^^^^^^^^^^^^^^^^
AttributeError: 'Study' object has no attribute 'series_instance_uid'

Exception at 25-02-2025 : 13-07-09
.............................................
In dicomdb
Message: Exception while getting series data sets
Traceback :
 ............
Traceback (most recent call last):
  File "C:\Users\45422\Desktop\API_version\ThesisProject2\dicom_server\core\dicomdb.py", line 188, in get_seriesRoot_dataset
    "SERIES", "patient_name", getattr(instance, "series_instance_uid")
                              ^^^^^^^^^^^^^^^^^^^^^^^^^^^^^^^^^^^^^^^^
AttributeError: 'Study' object has no attribute 'series_instance_uid'

Exception at 25-02-2025 : 13-07-09
.............................................
In dicomdb
Message: Exception while getting series data sets
Traceback :
 ............
Traceback (most recent call last):
  File "C:\Users\45422\Desktop\API_version\ThesisProject2\dicom_server\core\dicomdb.py", line 188, in get_seriesRoot_dataset
    "SERIES", "patient_name", getattr(instance, "series_instance_uid")
                              ^^^^^^^^^^^^^^^^^^^^^^^^^^^^^^^^^^^^^^^^
AttributeError: 'Study' object has no attribute 'series_instance_uid'

Exception at 25-02-2025 : 13-07-09
.............................................
In dicomdb
Message: Exception while getting series data sets
Traceback :
 ............
Traceback (most recent call last):
  File "C:\Users\45422\Desktop\API_version\ThesisProject2\dicom_server\core\dicomdb.py", line 188, in get_seriesRoot_dataset
    "SERIES", "patient_name", getattr(instance, "series_instance_uid")
                              ^^^^^^^^^^^^^^^^^^^^^^^^^^^^^^^^^^^^^^^^
AttributeError: 'Study' object has no attribute 'series_instance_uid'

Exception at 25-02-2025 : 13-07-09
.............................................
In dicomdb
Message: Exception while getting series data sets
Traceback :
 ............
Traceback (most recent call last):
  File "C:\Users\45422\Desktop\API_version\ThesisProject2\dicom_server\core\dicomdb.py", line 188, in get_seriesRoot_dataset
    "SERIES", "patient_name", getattr(instance, "series_instance_uid")
                              ^^^^^^^^^^^^^^^^^^^^^^^^^^^^^^^^^^^^^^^^
AttributeError: 'Study' object has no attribute 'series_instance_uid'

Exception at 25-02-2025 : 13-07-09
.............................................
In dicomdb
Message: Exception while getting series data sets
Traceback :
 ............
Traceback (most recent call last):
  File "C:\Users\45422\Desktop\API_version\ThesisProject2\dicom_server\core\dicomdb.py", line 188, in get_seriesRoot_dataset
    "SERIES", "patient_name", getattr(instance, "series_instance_uid")
                              ^^^^^^^^^^^^^^^^^^^^^^^^^^^^^^^^^^^^^^^^
AttributeError: 'Study' object has no attribute 'series_instance_uid'

Exception at 25-02-2025 : 13-07-09
.............................................
In dicomdb
Message: Exception while getting series data sets
Traceback :
 ............
Traceback (most recent call last):
  File "C:\Users\45422\Desktop\API_version\ThesisProject2\dicom_server\core\dicomdb.py", line 188, in get_seriesRoot_dataset
    "SERIES", "patient_name", getattr(instance, "series_instance_uid")
                              ^^^^^^^^^^^^^^^^^^^^^^^^^^^^^^^^^^^^^^^^
AttributeError: 'Study' object has no attribute 'series_instance_uid'

Exception at 25-02-2025 : 13-07-09
.............................................
In dicomdb
Message: Exception while getting series data sets
Traceback :
 ............
Traceback (most recent call last):
  File "C:\Users\45422\Desktop\API_version\ThesisProject2\dicom_server\core\dicomdb.py", line 188, in get_seriesRoot_dataset
    "SERIES", "patient_name", getattr(instance, "series_instance_uid")
                              ^^^^^^^^^^^^^^^^^^^^^^^^^^^^^^^^^^^^^^^^
AttributeError: 'Study' object has no attribute 'series_instance_uid'

Exception at 25-02-2025 : 13-07-09
.............................................
In dicomdb
Message: Exception while getting series data sets
Traceback :
 ............
Traceback (most recent call last):
  File "C:\Users\45422\Desktop\API_version\ThesisProject2\dicom_server\core\dicomdb.py", line 188, in get_seriesRoot_dataset
    "SERIES", "patient_name", getattr(instance, "series_instance_uid")
                              ^^^^^^^^^^^^^^^^^^^^^^^^^^^^^^^^^^^^^^^^
AttributeError: 'Study' object has no attribute 'series_instance_uid'

Exception at 25-02-2025 : 13-07-09
.............................................
In dicomdb
Message: Exception while getting series data sets
Traceback :
 ............
Traceback (most recent call last):
  File "C:\Users\45422\Desktop\API_version\ThesisProject2\dicom_server\core\dicomdb.py", line 188, in get_seriesRoot_dataset
    "SERIES", "patient_name", getattr(instance, "series_instance_uid")
                              ^^^^^^^^^^^^^^^^^^^^^^^^^^^^^^^^^^^^^^^^
AttributeError: 'Study' object has no attribute 'series_instance_uid'

Exception at 25-02-2025 : 13-07-09
.............................................
In dicomdb
Message: Exception while getting series data sets
Traceback :
 ............
Traceback (most recent call last):
  File "C:\Users\45422\Desktop\API_version\ThesisProject2\dicom_server\core\dicomdb.py", line 188, in get_seriesRoot_dataset
    "SERIES", "patient_name", getattr(instance, "series_instance_uid")
                              ^^^^^^^^^^^^^^^^^^^^^^^^^^^^^^^^^^^^^^^^
AttributeError: 'Study' object has no attribute 'series_instance_uid'

Exception at 25-02-2025 : 13-07-09
.............................................
In dicomdb
Message: Exception while getting series data sets
Traceback :
 ............
Traceback (most recent call last):
  File "C:\Users\45422\Desktop\API_version\ThesisProject2\dicom_server\core\dicomdb.py", line 188, in get_seriesRoot_dataset
    "SERIES", "patient_name", getattr(instance, "series_instance_uid")
                              ^^^^^^^^^^^^^^^^^^^^^^^^^^^^^^^^^^^^^^^^
AttributeError: 'Study' object has no attribute 'series_instance_uid'

Exception at 25-02-2025 : 13-07-09
.............................................
In dicomdb
Message: Exception while getting series data sets
Traceback :
 ............
Traceback (most recent call last):
  File "C:\Users\45422\Desktop\API_version\ThesisProject2\dicom_server\core\dicomdb.py", line 188, in get_seriesRoot_dataset
    "SERIES", "patient_name", getattr(instance, "series_instance_uid")
                              ^^^^^^^^^^^^^^^^^^^^^^^^^^^^^^^^^^^^^^^^
AttributeError: 'Study' object has no attribute 'series_instance_uid'

Exception at 25-02-2025 : 13-07-09
.............................................
In dicomdb
Message: Exception while getting series data sets
Traceback :
 ............
Traceback (most recent call last):
  File "C:\Users\45422\Desktop\API_version\ThesisProject2\dicom_server\core\dicomdb.py", line 188, in get_seriesRoot_dataset
    "SERIES", "patient_name", getattr(instance, "series_instance_uid")
                              ^^^^^^^^^^^^^^^^^^^^^^^^^^^^^^^^^^^^^^^^
AttributeError: 'Study' object has no attribute 'series_instance_uid'

Exception at 25-02-2025 : 13-07-09
.............................................
In dicomdb
Message: Exception while getting series data sets
Traceback :
 ............
Traceback (most recent call last):
  File "C:\Users\45422\Desktop\API_version\ThesisProject2\dicom_server\core\dicomdb.py", line 188, in get_seriesRoot_dataset
    "SERIES", "patient_name", getattr(instance, "series_instance_uid")
                              ^^^^^^^^^^^^^^^^^^^^^^^^^^^^^^^^^^^^^^^^
AttributeError: 'Study' object has no attribute 'series_instance_uid'

Exception at 25-02-2025 : 13-07-09
.............................................
In dicomdb
Message: Exception while getting series data sets
Traceback :
 ............
Traceback (most recent call last):
  File "C:\Users\45422\Desktop\API_version\ThesisProject2\dicom_server\core\dicomdb.py", line 188, in get_seriesRoot_dataset
    "SERIES", "patient_name", getattr(instance, "series_instance_uid")
                              ^^^^^^^^^^^^^^^^^^^^^^^^^^^^^^^^^^^^^^^^
AttributeError: 'Study' object has no attribute 'series_instance_uid'

Exception at 25-02-2025 : 13-07-09
.............................................
In dicomdb
Message: Exception while getting series data sets
Traceback :
 ............
Traceback (most recent call last):
  File "C:\Users\45422\Desktop\API_version\ThesisProject2\dicom_server\core\dicomdb.py", line 188, in get_seriesRoot_dataset
    "SERIES", "patient_name", getattr(instance, "series_instance_uid")
                              ^^^^^^^^^^^^^^^^^^^^^^^^^^^^^^^^^^^^^^^^
AttributeError: 'Study' object has no attribute 'series_instance_uid'

Exception at 25-02-2025 : 13-07-09
.............................................
In dicomdb
Message: Exception while getting series data sets
Traceback :
 ............
Traceback (most recent call last):
  File "C:\Users\45422\Desktop\API_version\ThesisProject2\dicom_server\core\dicomdb.py", line 188, in get_seriesRoot_dataset
    "SERIES", "patient_name", getattr(instance, "series_instance_uid")
                              ^^^^^^^^^^^^^^^^^^^^^^^^^^^^^^^^^^^^^^^^
AttributeError: 'Study' object has no attribute 'series_instance_uid'

Exception at 25-02-2025 : 13-07-09
.............................................
In dicomdb
Message: Exception while getting series data sets
Traceback :
 ............
Traceback (most recent call last):
  File "C:\Users\45422\Desktop\API_version\ThesisProject2\dicom_server\core\dicomdb.py", line 188, in get_seriesRoot_dataset
    "SERIES", "patient_name", getattr(instance, "series_instance_uid")
                              ^^^^^^^^^^^^^^^^^^^^^^^^^^^^^^^^^^^^^^^^
AttributeError: 'Study' object has no attribute 'series_instance_uid'

Exception at 25-02-2025 : 13-07-10
.............................................
In dicomdb
Message: Exception while getting series data sets
Traceback :
 ............
Traceback (most recent call last):
  File "C:\Users\45422\Desktop\API_version\ThesisProject2\dicom_server\core\dicomdb.py", line 188, in get_seriesRoot_dataset
    "SERIES", "patient_name", getattr(instance, "series_instance_uid")
                              ^^^^^^^^^^^^^^^^^^^^^^^^^^^^^^^^^^^^^^^^
AttributeError: 'Study' object has no attribute 'series_instance_uid'

Exception at 25-02-2025 : 13-07-10
.............................................
In dicomdb
Message: Exception while getting series data sets
Traceback :
 ............
Traceback (most recent call last):
  File "C:\Users\45422\Desktop\API_version\ThesisProject2\dicom_server\core\dicomdb.py", line 188, in get_seriesRoot_dataset
    "SERIES", "patient_name", getattr(instance, "series_instance_uid")
                              ^^^^^^^^^^^^^^^^^^^^^^^^^^^^^^^^^^^^^^^^
AttributeError: 'Study' object has no attribute 'series_instance_uid'

Exception at 25-02-2025 : 13-07-10
.............................................
In dicomdb
Message: Exception while getting series data sets
Traceback :
 ............
Traceback (most recent call last):
  File "C:\Users\45422\Desktop\API_version\ThesisProject2\dicom_server\core\dicomdb.py", line 188, in get_seriesRoot_dataset
    "SERIES", "patient_name", getattr(instance, "series_instance_uid")
                              ^^^^^^^^^^^^^^^^^^^^^^^^^^^^^^^^^^^^^^^^
AttributeError: 'Study' object has no attribute 'series_instance_uid'

Exception at 25-02-2025 : 13-07-10
.............................................
In dicomdb
Message: Exception while getting series data sets
Traceback :
 ............
Traceback (most recent call last):
  File "C:\Users\45422\Desktop\API_version\ThesisProject2\dicom_server\core\dicomdb.py", line 188, in get_seriesRoot_dataset
    "SERIES", "patient_name", getattr(instance, "series_instance_uid")
                              ^^^^^^^^^^^^^^^^^^^^^^^^^^^^^^^^^^^^^^^^
AttributeError: 'Study' object has no attribute 'series_instance_uid'

Exception at 25-02-2025 : 13-07-10
.............................................
In dicomdb
Message: Exception while getting series data sets
Traceback :
 ............
Traceback (most recent call last):
  File "C:\Users\45422\Desktop\API_version\ThesisProject2\dicom_server\core\dicomdb.py", line 188, in get_seriesRoot_dataset
    "SERIES", "patient_name", getattr(instance, "series_instance_uid")
                              ^^^^^^^^^^^^^^^^^^^^^^^^^^^^^^^^^^^^^^^^
AttributeError: 'Study' object has no attribute 'series_instance_uid'

Exception at 25-02-2025 : 13-07-10
.............................................
In dicomdb
Message: Exception while getting series data sets
Traceback :
 ............
Traceback (most recent call last):
  File "C:\Users\45422\Desktop\API_version\ThesisProject2\dicom_server\core\dicomdb.py", line 188, in get_seriesRoot_dataset
    "SERIES", "patient_name", getattr(instance, "series_instance_uid")
                              ^^^^^^^^^^^^^^^^^^^^^^^^^^^^^^^^^^^^^^^^
AttributeError: 'Study' object has no attribute 'series_instance_uid'

Exception at 25-02-2025 : 13-07-38
.............................................
In db
Message: Exception in SERIES level query
Traceback :
 ............
Traceback (most recent call last):
  File "C:\Users\45422\Desktop\API_version\ThesisProject2\dicom_server\core\dicomdb.py", line 120, in query_series_level
    matchedInstances = db.search(
                       ^^^^^^^^^^
  File "C:\Users\45422\Desktop\API_version\ThesisProject2\dicom_server\core\db.py", line 475, in search
    return _search_qr(model, identifier, session)
           ^^^^^^^^^^^^^^^^^^^^^^^^^^^^^^^^^^^^^^
  File "C:\Users\45422\Desktop\API_version\ThesisProject2\dicom_server\core\db.py", line 497, in _search_qr
    _check_identifier(identifier, model)
  File "C:\Users\45422\Desktop\API_version\ThesisProject2\dicom_server\core\db.py", line 375, in _check_identifier
    raise InvalidIdentifier(
db.InvalidIdentifier: The Identifier is missing a unique key for the 'STUDY' level

Exception at 25-02-2025 : 13-07-38
.............................................
In db
Message: Exception in handling C-FIND operation
Traceback :
 ............
Traceback (most recent call last):
  File "C:\Users\45422\Desktop\API_version\ThesisProject2\dicom_server\core\dicom_handlers.py", line 118, in handle_find
    matches = self.dicomdb.query_series_level(identifier)
              ^^^^^^^^^^^^^^^^^^^^^^^^^^^^^^^^^^^^^^^^^^^
  File "C:\Users\45422\Desktop\API_version\ThesisProject2\dicom_server\core\dicomdb.py", line 120, in query_series_level
    matchedInstances = db.search(
                       ^^^^^^^^^^
  File "C:\Users\45422\Desktop\API_version\ThesisProject2\dicom_server\core\db.py", line 475, in search
    return _search_qr(model, identifier, session)
           ^^^^^^^^^^^^^^^^^^^^^^^^^^^^^^^^^^^^^^
  File "C:\Users\45422\Desktop\API_version\ThesisProject2\dicom_server\core\db.py", line 497, in _search_qr
    _check_identifier(identifier, model)
  File "C:\Users\45422\Desktop\API_version\ThesisProject2\dicom_server\core\db.py", line 375, in _check_identifier
    raise InvalidIdentifier(
db.InvalidIdentifier: The Identifier is missing a unique key for the 'STUDY' level

Exception at 25-02-2025 : 13-09-05
.............................................
In db
Message: Exception in SERIES level query
Traceback :
 ............
Traceback (most recent call last):
  File "C:\Users\45422\Desktop\API_version\ThesisProject2\dicom_server\core\dicomdb.py", line 120, in query_series_level
    matchedInstances = db.search(
                       ^^^^^^^^^^
  File "C:\Users\45422\Desktop\API_version\ThesisProject2\dicom_server\core\db.py", line 475, in search
    return _search_qr(model, identifier, session)
           ^^^^^^^^^^^^^^^^^^^^^^^^^^^^^^^^^^^^^^
  File "C:\Users\45422\Desktop\API_version\ThesisProject2\dicom_server\core\db.py", line 497, in _search_qr
    _check_identifier(identifier, model)
  File "C:\Users\45422\Desktop\API_version\ThesisProject2\dicom_server\core\db.py", line 375, in _check_identifier
    raise InvalidIdentifier(
db.InvalidIdentifier: The Identifier is missing a unique key for the 'STUDY' level

Exception at 25-02-2025 : 13-09-05
.............................................
In db
Message: Exception in handling C-FIND operation
Traceback :
 ............
Traceback (most recent call last):
  File "C:\Users\45422\Desktop\API_version\ThesisProject2\dicom_server\core\dicom_handlers.py", line 118, in handle_find
    matches = self.dicomdb.query_series_level(identifier)
              ^^^^^^^^^^^^^^^^^^^^^^^^^^^^^^^^^^^^^^^^^^^
  File "C:\Users\45422\Desktop\API_version\ThesisProject2\dicom_server\core\dicomdb.py", line 120, in query_series_level
    matchedInstances = db.search(
                       ^^^^^^^^^^
  File "C:\Users\45422\Desktop\API_version\ThesisProject2\dicom_server\core\db.py", line 475, in search
    return _search_qr(model, identifier, session)
           ^^^^^^^^^^^^^^^^^^^^^^^^^^^^^^^^^^^^^^
  File "C:\Users\45422\Desktop\API_version\ThesisProject2\dicom_server\core\db.py", line 497, in _search_qr
    _check_identifier(identifier, model)
  File "C:\Users\45422\Desktop\API_version\ThesisProject2\dicom_server\core\db.py", line 375, in _check_identifier
    raise InvalidIdentifier(
db.InvalidIdentifier: The Identifier is missing a unique key for the 'STUDY' level

